<?xml version='1.0' encoding='utf-8'?>
<robot name="Biomimetic">
    <link name="Rear-Fin">
        <inertial>
            <origin xyz="0.00027484232876314965 1.667656435433429e-07 0.015001340935642522" rpy="0.0 -0.0 0.0" />
            <mass value="0.0009810419371682414" />
            <inertia ixx="6.381203867330296e-08" iyy="6.387757634909987e-08" izz="6.674473572878365e-10" ixy="-5.627546022190751e-12" iyz="2.698986613699847e-12" ixz="-3.075078312341319e-11" />
        </inertial>
        <visual name="Rear-Fin_visual">
            <origin xyz="-0.1685 -0.025000000745058062 0.030000013515570533" rpy="0.0 -0.0 0.0" />
            <geometry>
                <mesh filename="meshes/Rear-Fin.stl" scale="0.001 0.001 0.001" />
            </geometry>
        </visual>
        <collision name="Rear-Fin_collision">
            <origin xyz="-0.1685 -0.025000000745058062 0.030000013515570533" rpy="0.0 -0.0 0.0" />
            <geometry>
                <mesh filename="meshes/Rear-Fin.stl" scale="0.001 0.001 0.001" />
            </geometry>
        </collision>
    </link>
    <link name="Body">
        <inertial>
            <origin xyz="0.013459196472192202 0.025000009593440047 -0.004835075808883665" rpy="0.0 0.0 0.0" />
            <mass value="5.0792171674360125" />
            <inertia ixx="0.00411399632785542" iyy="0.024616479993953312" izz="0.021191256368660247" ixy="-2.2659308847663984e-10" iyz="-2.998658873293314e-11" ixz="0.0002704678775184273" />
        </inertial>
        <visual name="Body_visual">
            <origin xyz="0.0 0.0 0.0" rpy="0.0 0.0 0.0" />
            <geometry>
                <mesh filename="meshes/Body.stl" scale="0.001 0.001 0.001" />
            </geometry>
        </visual>
        <collision name="Body_collision">
            <origin xyz="0.0 0.0 0.0" rpy="0.0 0.0 0.0" />
            <geometry>
                <mesh filename="meshes/Body.stl" scale="0.001 0.001 0.001" />
            </geometry>
        </collision>
    </link>
    <link name="Front-Fin">
        <inertial>
            <origin xyz="0.0067052120585023925 0.0013226675934459387 0.018054674936638017" rpy="0.0 -0.0 0.0" />
            <mass value="0.04870751907868534" />
            <inertia ixx="1.995058528853168e-05" iyy="2.3622311751599388e-05" izz="4.361984471852335e-06" ixy="-6.796445946854678e-07" iyz="-8.922467346019635e-09" ixz="-1.999389642297491e-08" />
        </inertial>
        <visual name="Front-Fin_visual">
            <origin xyz="0.0009848077530122087 0.00017364817766692993 -0.0069999974690213304" rpy="1.5707963267948966 -5.88933255696368e-17 0.17453292519943317" />
            <geometry>
                <mesh filename="meshes/Front-Fin.stl" scale="0.001 0.001 0.001" />
            </geometry>
        </visual>
        <collision name="Front-Fin_collision">
            <origin xyz="0.0009848077530122087 0.00017364817766692993 -0.0069999974690213304" rpy="1.5707963267948966 -5.88933255696368e-17 0.17453292519943317" />
            <geometry>
                <mesh filename="meshes/Front-Fin.stl" scale="0.001 0.001 0.001" />
            </geometry>
        </collision>
    </link>
    <joint name="Body_Revolute-1" type="revolute">
        <origin xyz="0.1685 0.025 4.2000000000000004e-06" rpy="3.141592653589793 -0.0 0.0" />
        <parent link="Body" />
        <child link="Rear-Fin" />
        <axis xyz="0.0 0.0 1.0" />
        <limit lower="-0.523599" upper="0.523599" effort="1000000" velocity="1000000" />
    </joint>
    <joint name="Body_Revolute-2" type="revolute">
        <origin xyz="-0.001 0.00707888 0.0" rpy="-1.5707963267948966 -0.0 0.0" />
        <parent link="Body" />
        <child link="Front-Fin" />
        <axis xyz="0.0 0.0 1.0" />
        <limit lower="-0.174533" upper="0.392699" effort="1000000" velocity="1000000" />
    </joint>
</robot>